multiprocessing.pool.RemoteTraceback: 
"""
Traceback (most recent call last):
  File "/opt/anaconda/anaconda3/envs/pt120/lib/python3.6/multiprocessing/pool.py", line 119, in worker
    result = (True, func(*args, **kwds))
  File "/opt/anaconda/anaconda3/envs/pt120/lib/python3.6/multiprocessing/pool.py", line 47, in starmapstar
    return list(itertools.starmap(args[0], args[1]))
TypeError: take_pair_wise_object_pr() missing 1 required positional argument: 'trail'
"""

The above exception was the direct cause of the following exception:

Traceback (most recent call last):
  File "object_pr.py", line 333, in <module>
    pool.starmap(take_pair_wise_object_pr, args_list)
  File "/opt/anaconda/anaconda3/envs/pt120/lib/python3.6/multiprocessing/pool.py", line 274, in starmap
    return self._map_async(func, iterable, starmapstar, chunksize).get()
  File "/opt/anaconda/anaconda3/envs/pt120/lib/python3.6/multiprocessing/pool.py", line 644, in get
    raise self._value
TypeError: take_pair_wise_object_pr() missing 1 required positional argument: 'trail'
